Workbook

Sheet TEMPLATE RAB
A2: INGAT YA!
C3: RENCARA BIAYA ANGGARAN (RAB) EVENT
M4: NORMA BIAYA
A9: Selalu klik "Trust Workbook Link" jika muncul notifikasi tersebut diatas layar | C9: Event ID | E9: 244
A10: Hanya Cell warna putih yang perlu diinput ✅️ | C10: Kategori Event | E10: L2
A11: Cell warna Abu-Abu terkunci & tidak bisa diubah❌ | C11: Nama Kegiatan | E11: =IFERROR(VLOOKUP(E9,#REF!, 3, FALSE), "Data Tidak Ditemukan") -> Data Tidak Ditemukan
A12: Jika "Dropdown" pada cell tertentu tidak muncul semua list nya --> Resfresh laman 🔄️ | C12: Nama Training Support (TS) | E12: =IFERROR(VLOOKUP(E9,#REF!, 7, FALSE), "Data Tidak Ditemukan") -> Data Tidak Ditemukan
A13: Jika urgent perlu edit cell yang terkunci--> hubungi Koordinator TS dan konfirmasi ke Manager TCU Area | C13: Tanggal Kegiatan (kelas offline) | E13: 45961 | F13: s/d | G13: 45961
A14: Jika Nama Event dan Nama TS tidak ditemukan --> Request update Database Event ke Koordinator TS | C14: Akomodasi | E14: Tidak ditanggung penyelenggara
C15: Lokasi | E15: Jakarta
A16: ⭐Kolom Paket Biaya | C16: Indeks Lokasi | E16: Semarang (LA-3) | F16: =VLOOKUP(E16, 'INDEKS RAB'!$G$3:$H$13, 2, FALSE) -> 1
A17: Jika Paket Biaya yang diminta di FK/JK punya Norma Biaya --> Isi di tabel "PAKET BIAYA SESUAI NORMA BIAYA" | C17: Cost Center | E17: T752E25 | F17: =VLOOKUP(E17, 'COST CENTER & BEBAN ANGGARAN'!$B$4:$C$8, 2, FALSE) -> SoGTM
A18: Jika Paket Biaya yang diminta di FK/JK tidak punya Norma Biaya (Paket Custom) --> Input manual di tabel "PAKET BIAYA DILUAR NORMA BIAYA" | C18: Akun Beban Anggaran | E18: 51505007 | F18: =VLOOKUP(E18, 'COST CENTER & BEBAN ANGGARAN'!$E$4:$F$7, 2, FALSE) -> Beban Peralatan Diklat
A20: ⭐Kolom VOL/FREQ
A21: Paket Biaya dengan satuan bukan "Event" otomatis terisi "0" dan wajib input manual sesuai FK/JK. | C21: PAKET BIAYA STANDAR
A22: Paket Biaya dengan satuan "Event" otomatis terisi angka "1" dan tidak boleh diedit. | C22: Vendor | D22: Koperasi Konsumen Karyawan PT. Telkom Saraswati
C23: No | D23: Paket Biaya | E23: SATUAN | F23: QTY | G23: VOL/FREQ | H23: NORMA BIAYA | I23: HARGA FINAL | J23: TOTAL | K23: KETERANGAN
A24: ⭐Kolom HARGA FINAL | C24: 1 | D24: Training Kit (Note Book, Pena, Name Tag) | E24: =IFERROR( INDEX('NORMA BIAYA'!$O$8:$O$81, MATCH(D24, 'NORMA BIAYA'!$C$8:$C$81, 0) ), "" ) -> Pax | G24: =IF(D24="","",IF(E24 ="Event",1,0)) -> 0 | H24: {=IFERROR( INDEX('NORMA BIAYA'!$D$8:$N$81, MATCH(1,('NORMA BIAYA'!$B$8:$B$81=$E$10)*('NORMA BIAYA'!$C$8:$C$81=D24),0), MATCH($E$16,'NORMA BIAYA'!$D$6:$N$6,0) ), "" )} -> 50000 | J24: =IF(OR(F24="",G24="",I24=""),"",F24*G24*I24)
A25: Jika harga satuan di FK/JK lebih kecil atau sama dengan Norma Biaya => Input harga final sesuai FK/JK | C25: 2 | D25: Konsumsi (Makan 1x, Snack 2x) | E25: =IFERROR( INDEX('NORMA BIAYA'!$O$8:$O$81, MATCH(D25, 'NORMA BIAYA'!$C$8:$C$81, 0) ), "" ) -> Hari | G25: =IF(D25="","",IF(E25 ="Event",1,0)) -> 0 | H25: {=IFERROR( INDEX('NORMA BIAYA'!$D$8:$N$81, MATCH(1,('NORMA BIAYA'!$B$8:$B$81=$E$10)*('NORMA BIAYA'!$C$8:$C$81=D25),0), MATCH($E$16,'NORMA BIAYA'!$D$6:$N$6,0) ), "" )} -> 216000 | J25: =IF(OR(F25="",G25="",I25=""),"",F25*G25*I25)
A26: Jika harga satuan di FK/JK lebih besar dari Norma Biaya => Input harga final sesuai Norma Biaya | C26: 3 | D26: Akomodasi Hotel Fasilitator (2 org/kamar sd BP3 & 1 org/kamar BP2 & 1) | E26: =IFERROR( INDEX('NORMA BIAYA'!$O$8:$O$81, MATCH(D26, 'NORMA BIAYA'!$C$8:$C$81, 0) ), "" ) -> Hari | G26: =IF(D26="","",IF(E26 ="Event",1,0)) -> 0 | H26: {=IFERROR( INDEX('NORMA BIAYA'!$D$8:$N$81, MATCH(1,('NORMA BIAYA'!$B$8:$B$81=$E$10)*('NORMA BIAYA'!$C$8:$C$81=D26),0), MATCH($E$16,'NORMA BIAYA'!$D$6:$N$6,0) ), "" )} -> 960000 | J26: =IF(OR(F26="",G26="",I26=""),"",F26*G26*I26)
C27: 4 | D27: Akomodasi Hotel Peserta (R1& L1= 2 org/kamar, R2 & L2= 1 org/kamar) | E27: =IFERROR( INDEX('NORMA BIAYA'!$O$8:$O$81, MATCH(D27, 'NORMA BIAYA'!$C$8:$C$81, 0) ), "" ) -> Hari | G27: =IF(D27="","",IF(E27 ="Event",1,0)) -> 0 | H27: {=IFERROR( INDEX('NORMA BIAYA'!$D$8:$N$81, MATCH(1,('NORMA BIAYA'!$B$8:$B$81=$E$10)*('NORMA BIAYA'!$C$8:$C$81=D27),0), MATCH($E$16,'NORMA BIAYA'!$D$6:$N$6,0) ), "" )} -> 840000 | J27: =IF(OR(F27="",G27="",I27=""),"",F27*G27*I27)
A28: ⭐CELL VENDOR | C28: 7 | D28: Perlengkapan Kelas (Flipchart, Spidol, Baterai, Kertas, dll) | E28: =IFERROR( INDEX('NORMA BIAYA'!$O$8:$O$81, MATCH(D28, 'NORMA BIAYA'!$C$8:$C$81, 0) ), "" ) -> Event | G28: =IF(D28="","",IF(E28 ="Event",1,0)) -> 1 | H28: {=IFERROR( INDEX('NORMA BIAYA'!$D$8:$N$81, MATCH(1,('NORMA BIAYA'!$B$8:$B$81=$E$10)*('NORMA BIAYA'!$C$8:$C$81=D28),0), MATCH($E$16,'NORMA BIAYA'!$D$6:$N$6,0) ), "" )} -> 500000 | J28: =IF(OR(F28="",G28="",I28=""),"",F28*G28*I28)
A29: Input manual sesuai Vendor yang diminta pada FK/JK. | C29: 8 | D29: Alat dan Bahan untuk Praktikum/Game (Bila diperlukan) | E29: =IFERROR( INDEX('NORMA BIAYA'!$O$8:$O$81, MATCH(D29, 'NORMA BIAYA'!$C$8:$C$81, 0) ), "" ) -> Pax | G29: =IF(D29="","",IF(E29 ="Event",1,0)) -> 0 | H29: {=IFERROR( INDEX('NORMA BIAYA'!$D$8:$N$81, MATCH(1,('NORMA BIAYA'!$B$8:$B$81=$E$10)*('NORMA BIAYA'!$C$8:$C$81=D29),0), MATCH($E$16,'NORMA BIAYA'!$D$6:$N$6,0) ), "" )} -> 1800000 | J29: =IF(OR(F29="",G29="",I29=""),"",F29*G29*I29)
C30: 9 | D30: Learning Gift | E30: =IFERROR( INDEX('NORMA BIAYA'!$O$8:$O$81, MATCH(D30, 'NORMA BIAYA'!$C$8:$C$81, 0) ), "" ) -> Event | G30: =IF(D30="","",IF(E30 ="Event",1,0)) -> 1 | H30: {=IFERROR( INDEX('NORMA BIAYA'!$D$8:$N$81, MATCH(1,('NORMA BIAYA'!$B$8:$B$81=$E$10)*('NORMA BIAYA'!$C$8:$C$81=D30),0), MATCH($E$16,'NORMA BIAYA'!$D$6:$N$6,0) ), "" )} -> 1200000 | J30: =IF(OR(F30="",G30="",I30=""),"",F30*G30*I30)
C31: 10 | D31: Apresiasi (Best Participant) | E31: =IFERROR( INDEX('NORMA BIAYA'!$O$8:$O$81, MATCH(D31, 'NORMA BIAYA'!$C$8:$C$81, 0) ), "" ) -> Event | G31: =IF(D31="","",IF(E31 ="Event",1,0)) -> 1 | H31: {=IFERROR( INDEX('NORMA BIAYA'!$D$8:$N$81, MATCH(1,('NORMA BIAYA'!$B$8:$B$81=$E$10)*('NORMA BIAYA'!$C$8:$C$81=D31),0), MATCH($E$16,'NORMA BIAYA'!$D$6:$N$6,0) ), "" )} -> 3000000 | J31: =IF(OR(F31="",G31="",I31=""),"",F31*G31*I31)
C32: 11 | D32: Recording/Dokumentasi Event | E32: =IFERROR( INDEX('NORMA BIAYA'!$O$8:$O$81, MATCH(D32, 'NORMA BIAYA'!$C$8:$C$81, 0) ), "" ) -> Event | G32: =IF(D32="","",IF(E32 ="Event",1,0)) -> 1 | H32: {=IFERROR( INDEX('NORMA BIAYA'!$D$8:$N$81, MATCH(1,('NORMA BIAYA'!$B$8:$B$81=$E$10)*('NORMA BIAYA'!$C$8:$C$81=D32),0), MATCH($E$16,'NORMA BIAYA'!$D$6:$N$6,0) ), "" )} -> 1800000 | J32: =IF(OR(F32="",G32="",I32=""),"",F32*G32*I32)
A33: Cek ulang jika satuan paket biaya adalah "Event" = maka Vol/Freq nya wajib "1" | C33: 12 | D33: Kendaraan sewa utk ALP/Site Visit | E33: =IFERROR( INDEX('NORMA BIAYA'!$O$8:$O$81, MATCH(D33, 'NORMA BIAYA'!$C$8:$C$81, 0) ), "" ) -> Event | G33: =IF(D33="","",IF(E33 ="Event",1,0)) -> 1 | H33: {=IFERROR( INDEX('NORMA BIAYA'!$D$8:$N$81, MATCH(1,('NORMA BIAYA'!$B$8:$B$81=$E$10)*('NORMA BIAYA'!$C$8:$C$81=D33),0), MATCH($E$16,'NORMA BIAYA'!$D$6:$N$6,0) ), "" )} -> 4440000 | J33: =IF(OR(F33="",G33="",I33=""),"",F33*G33*I33)
C34: 13 | D34: Makan Malam Fasilitator | E34: =IFERROR( INDEX('NORMA BIAYA'!$O$8:$O$81, MATCH(D34, 'NORMA BIAYA'!$C$8:$C$81, 0) ), "" ) -> Hari | G34: =IF(D34="","",IF(E34 ="Event",1,0)) -> 0 | H34: {=IFERROR( INDEX('NORMA BIAYA'!$D$8:$N$81, MATCH(1,('NORMA BIAYA'!$B$8:$B$81=$E$10)*('NORMA BIAYA'!$C$8:$C$81=D34),0), MATCH($E$16,'NORMA BIAYA'!$D$6:$N$6,0) ), "" )} -> 180000 | J34: =IF(OR(F34="",G34="",I34=""),"",F34*G34*I34)
C35: 14 | D35: Makan Malam Peserta | E35: =IFERROR( INDEX('NORMA BIAYA'!$O$8:$O$81, MATCH(D35, 'NORMA BIAYA'!$C$8:$C$81, 0) ), "" ) -> Hari | G35: =IF(D35="","",IF(E35 ="Event",1,0)) -> 0 | H35: {=IFERROR( INDEX('NORMA BIAYA'!$D$8:$N$81, MATCH(1,('NORMA BIAYA'!$B$8:$B$81=$E$10)*('NORMA BIAYA'!$C$8:$C$81=D35),0), MATCH($E$16,'NORMA BIAYA'!$D$6:$N$6,0) ), "" )} -> 180000 | J35: =IF(OR(F35="",G35="",I35=""),"",F35*G35*I35)
C36: 15 | E36: =IFERROR( INDEX('NORMA BIAYA'!$O$8:$O$81, MATCH(D36, 'NORMA BIAYA'!$C$8:$C$81, 0) ), "" ) | G36: =IF(D36="","",IF(E36 ="Event",1,0)) | H36: {=IFERROR( INDEX(#REF!, MATCH(1,(#REF!=$E$10)*(#REF!=D36),0), MATCH($E$16,#REF!,0) ), "" )} | J36: =IF(OR(F36="",G36="",I36=""),"",F36*G36*I36)
I37: SUB TOTAL I | J37: =SUM(J24:J36) -> 0
C39: PAKET BIAYA TAMBAHAN
C40: Vendor
C41: No | D41: Paket Biaya | E41: SATUAN | F41: QTY | G41: VOL/FREQ | H41: HARGA FINAL | I41: TOTAL | J41: KETERANGAN
C42: 1 | D42: cetak sertifikat | I42: =IF(OR(F42="",G42="",H42=""),"",F42*G42*H42)
C43: 2 | I43: =IF(OR(F43="",G43="",H43=""),"",F43*G43*H43)
C44: 3 | I44: =IF(OR(F44="",G44="",H44=""),"",F44*G44*H44)
C45: 4 | I45: =IF(OR(F45="",G45="",H45=""),"",F45*G45*H45)
C46: 7 | I46: =IF(OR(F46="",G46="",H46=""),"",F46*G46*H46)
C47: 8 | I47: =IF(OR(F47="",G47="",H47=""),"",F47*G47*H47)
...

Sheet INDEKS RAB
C2: KODE | D2: LOKASI | E2: NILAI INDEKS | G2: LOKASI | H2: NILAI INDEKS
C3: LA-1 | D3: Sumatera | E3: 1.31 | G3: Sumatera (LA-1) | H3: 1.31
D4: Jakarta, DKI Jakarta | E4: 1.51 | G4: Jakarta (LA-1) | H4: 1.51
C5: LA-2 | D5: Bandung, Jawa Barat | E5: 1.28 | G5: Bandung (LA-2) | H5: 1.28
C6: LA-3 | D6: Semarang, Jawa Tengah | E6: 1 | G6: Semarang (LA-3) | H6: 1
D7: Surabaya, Jawa Timur | E7: 1.45 | G7: Surabaya (LA-3) | H7: 1.45
D8: Bali | E8: 1.45 | G8: Bali (LA-3) | H8: 1.45
D9: Nusa Tenggara | E9: 1.45 | G9: Nusa Tenggara (LA-3) | H9: 1.45
C10: LA-4 | D10: Kalimantan | E10: 1.25 | G10: Kalimantan (LA-4) | H10: 1.25
D11: Sulawesi | E11: 1.49 | G11: Sulawesi (LA-4) | H11: 1.49
D12: Maluku | E12: 1.49 | G12: Maluku (LA-4) | H12: 1.49
D13: Papua | E13: 1.49 | G13: Papua (LA-4) | H13: 1.49

Sheet COST CENTER & BEBAN ANGGARAN
B2: KODE ANGGARAN | E2: AKUN BEBAN ANGGARAN
B3: KODE | C3: Cost Center | E3: KODE | F3: NAMA AKUN
B4: T752E25 | C4: SoGTM | E4: 51505001 | F4: Beban Pelatihan Dalam Negeri
B5: T752F25 | C5: SoECT | E5: 51505007 | F5: Beban Peralatan Diklat
B6: T752G25 | C6: SoDSNP | E6: 51505015 | F6: Beban Pembekalan Purnabakti
B7: T752H25 | C7: SoDI | E7: 52100904 | F7: Beban Non Usaha
B8: T752K25 | C8: LIRF

Sheet NORMA BIAYA
B2: HARGA SATUAN MAKSIMAL RAB EVENT
B6: KATEGORI | C6: ITEM | D6: Sumatera (LA-1) | E6: Jakarta (LA-1) | F6: Bandung (LA-2) | G6: Semarang (LA-3) | H6: Surabaya (LA-3) | I6: Bali (LA-3) | J6: Nusa Tenggara (LA-3) | K6: Kalimantan (LA-4) | L6: Sulawesi (LA-4) | M6: Maluku (LA-4) | N6: Papua (LA-4) | O6: SATUAN | P6: VOL/FREQ
D7: 1.31 | E7: 1.51 | F7: 1.28 | G7: 1 | H7: 1.45 | I7: 1.45 | J7: 1.45 | K7: 1.25 | L7: 1.49 | M7: 1.49 | N7: 1.49 | AI7: Kelas | AJ7: 500
B8: R1 | C8: Training Kit (Note Book, Pena, Name Tag) | D8: 50000 | E8: 50000 | F8: 50000 | G8: 50000 | H8: 50000 | I8: 50000 | J8: 50000 | K8: 50000 | L8: 50000 | M8: 50000 | N8: 50000 | O8: Pax | P8: 0 | AI8: training | AJ8: 50
B9: R2 | C9: Training Kit (Note Book, Pena, Name Tag) | D9: 50000 | E9: =50000*E7 -> 75500 | F9: 50000 | G9: 50000 | H9: 50000 | I9: 50000 | J9: 50000 | K9: 50000 | L9: 50000 | M9: 50000 | N9: 50000 | O9: Pax | P9: 0
B10: L1 | C10: Training Kit (Note Book, Pena, Name Tag) | D10: 50000 | E10: 50000 | F10: 50000 | G10: 50000 | H10: 50000 | I10: 50000 | J10: 50000 | K10: 50000 | L10: 50000 | M10: 50000 | N10: 50000 | O10: Pax | P10: 0
B11: L2 | C11: Training Kit (Note Book, Pena, Name Tag) | D11: 50000 | E11: =50000*E7 -> 75500 | F11: 50000 | G11: 50000 | H11: 50000 | I11: 50000 | J11: 50000 | K11: 50000 | L11: 50000 | M11: 50000 | N11: 50000 | O11: Pax | P11: 0
D12: Sumatera (LA-1) | E12: Jakarta (LA-1) | F12: Bandung (LA-2) | G12: Semarang (LA-3) | H12: Surabaya (LA-3) | I12: Bali (LA-3) | J12: Nusa Tenggara (LA-3) | K12: Kalimantan (LA-4) | L12: Sulawesi (LA-4) | M12: Maluku (LA-4) | N12: Papua (LA-4)
B13: R1 | C13: Konsumsi (Makan 1x, Snack 2x) | D13: =120000*D7 -> 157200 | E13: =120000*E7 -> 181200 | F13: =120000*F7 -> 153600 | G13: =120000*G7 -> 120000 | H13: =120000*H7 -> 174000 | I13: =120000*I7 -> 174000 | J13: =120000*J7 -> 174000 | K13: =120000*K7 -> 150000 | ... N13: =120000*N7 -> 178800 | O13: Hari | P13: 0
B14: R2 | C14: Konsumsi (Makan 1x, Snack 2x) | D14: =180000*D7 -> 235800 | E14: =180000*E7 -> 271800 | F14: =180000*F7 -> 230400 | G14: =180000*G7 -> 180000 | H14: =180000*H7 -> 261000 | I14: =180000*I7 -> 261000 | J14: =180000*J7 -> 261000 | K14: =180000*K7 -> 225000 | ... N14: =180000*N7 -> 268200 | O14: Hari | P14: 0
B15: L1 | C15: Konsumsi (Makan 1x, Snack 2x) | D15: =180000*D7*80% -> 188640 | E15: =180000*E7*80% -> 217440 | F15: =180000*F7*80% -> 184320 | G15: =180000*G7*80% -> 144000 | H15: =180000*H7*80% -> 208800 | I15: =180000*I7*80% -> 208800 | J15: =180000*J7*80% -> 208800 | K15: =180000*K7*80% -> 180000 | ... N15: =180000*N7*80% -> 214560 | O15: Hari | P15: 0
B16: L2 | C16: Konsumsi (Makan 1x, Snack 2x) | D16: =180000*D7*120% -> 282960 | E16: =180000*E7*120% -> 326160 | F16: =180000*F7*120% -> 276480 | G16: =180000*G7*120% -> 216000 | H16: =180000*H7*120% -> 313200 | I16: =180000*I7*120% -> 313200 | J16: =180000*J7*120% -> 313200 | K16: =180000*K7*120% -> 270000 | ... N16: =180000*N7*120% -> 321840 | O16: Hari | P16: 0
D17: Sumatera (LA-1) | E17: Jakarta (LA-1) | F17: Bandung (LA-2) | G17: Semarang (LA-3) | H17: Surabaya (LA-3) | I17: Bali (LA-3) | J17: Nusa Tenggara (LA-3) | K17: Kalimantan (LA-4) | L17: Sulawesi (LA-4) | M17: Maluku (LA-4) | N17: Papua (LA-4)
B18: R1 | C18: Akomodasi Hotel Peserta (R1& L1= 2 org/kamar, R2 & L2= 1 org/kamar) | D18: =500000*D7 -> 655000 | E18: =500000*E7 -> 755000 | F18: =500000*F7 -> 640000 | G18: =500000*G7 -> 500000 | H18: =500000*H7 -> 725000 | I18: =500000*I7 -> 725000 | J18: =500000*J7 -> 725000 | K18: =500000*K7 -> 625000 | ... N18: =500000*N7 -> 745000 | O18: Hari | P18: 0
B19: R2 | C19: Akomodasi Hotel Peserta (R1& L1= 2 org/kamar, R2 & L2= 1 org/kamar) | D19: =700000*D7 -> 917000 | E19: =700000*E7 -> 1057000 | F19: =700000*F7 -> 896000 | G19: =700000*G7 -> 700000 | H19: =700000*H7 -> 1015000 | I19: =700000*I7 -> 1015000 | J19: =700000*J7 -> 1015000 | K19: =700000*K7 -> 875000 | ... N19: =700000*N7 -> 1043000 | O19: Hari | P19: 0
B20: L1 | C20: Akomodasi Hotel Peserta (R1& L1= 2 org/kamar, R2 & L2= 1 org/kamar) | D20: =700000*D7*80% -> 733600 | E20: =700000*E7*80% -> 845600 | F20: =700000*F7*80% -> 716800 | G20: =700000*G7*80% -> 560000 | H20: =700000*H7*80% -> 812000 | I20: =700000*I7*80% -> 812000 | J20: =700000*J7*80% -> 812000 | K20: =700000*K7*80% -> 700000 | ... N20: =700000*N7*80% -> 834400 | O20: Hari | P20: 0
B21: L2 | C21: Akomodasi Hotel Peserta (R1& L1= 2 org/kamar, R2 & L2= 1 org/kamar) | D21: =700000*D7*120% -> 1100400 | E21: =700000*E7*120% -> 1268400 | F21: =700000*F7*120% -> 1075200 | G21: =700000*G7*120% -> 840000 | H21: =700000*H7*120% -> 1218000 | I21: =700000*I7*120% -> 1218000 | J21: =700000*J7*120% -> 1218000 | K21: =700000*K7*120% -> 1050000 | ... N21: =700000*N7*120% -> 1251600 | O21: Hari | P21: 0
D22: Sumatera (LA-1) | E22: Jakarta (LA-1) | F22: Bandung (LA-2) | G22: Semarang (LA-3) | H22: Surabaya (LA-3) | I22: Bali (LA-3) | J22: Nusa Tenggara (LA-3) | K22: Kalimantan (LA-4) | L22: Sulawesi (LA-4) | M22: Maluku (LA-4) | N22: Papua (LA-4)
B23: R1 | C23: Makan Malam Fasilitator | D23: =100000*D7 -> 131000 | E23: =100000*E7 -> 151000 | F23: =100000*F7 -> 128000 | G23: =100000*G7 -> 100000 | H23: =100000*H7 -> 145000 | I23: =100000*I7 -> 145000 | J23: =100000*J7 -> 145000 | K23: =100000*K7 -> 125000 | ... N23: =100000*N7 -> 149000 | O23: Hari | P23: 0
B24: R2 | C24: Makan Malam Fasilitator | D24: =150000*D7 -> 196500 | E24: =150000*E7 -> 226500 | F24: =150000*F7 -> 192000 | G24: =150000*G7 -> 150000 | H24: =150000*H7 -> 217500 | I24: =150000*I7 -> 217500 | J24: =150000*J7 -> 217500 | K24: =150000*K7 -> 187500 | ... N24: =150000*N7 -> 223500 | O24: Hari | P24: 0
B25: L1 | C25: Makan Malam Fasilitator | D25: =150000*D7*80% -> 157200 | E25: =150000*E7*80% -> 181200 | F25: =150000*F7*80% -> 153600 | G25: =150000*G7*80% -> 120000 | H25: =150000*H7*80% -> 174000 | I25: =150000*I7*80% -> 174000 | J25: =150000*J7*80% -> 174000 | K25: =150000*K7*80% -> 150000 | ... N25: =150000*N7*80% -> 178800 | O25: Hari | P25: 0
B26: L2 | C26: Makan Malam Fasilitator | D26: =150000*D7*120% -> 235800 | E26: =150000*E7*120% -> 271800 | F26: =150000*F7*120% -> 230400 | G26: =150000*G7*120% -> 180000 | H26: =150000*H7*120% -> 261000 | I26: =150000*I7*120% -> 261000 | J26: =150000*J7*120% -> 261000 | K26: =150000*K7*120% -> 225000 | ... N26: =150000*N7*120% -> 268200 | O26: Hari | P26: 0
D27: Sumatera (LA-1) | E27: Jakarta (LA-1) | F27: Bandung (LA-2) | G27: Semarang (LA-3) | H27: Surabaya (LA-3) | I27: Bali (LA-3) | J27: Nusa Tenggara (LA-3) | K27: Kalimantan (LA-4) | L27: Sulawesi (LA-4) | M27: Maluku (LA-4) | N27: Papua (LA-4)
B28: R1 | C28: Goody Bag (Buku/Makanan Sehat/Oleh-oleh) | D28: =150000*D7 -> 196500 | E28: =150000*E7 -> 226500 | F28: =150000*F7 -> 192000 | G28: =150000*G7 -> 150000 | H28: =150000*H7 -> 217500 | I28: =150000*I7 -> 217500 | J28: =150000*J7 -> 217500 | K28: =150000*K7 -> 187500 | ... N28: =150000*N7 -> 223500 | O28: Pcs | P28: 0
B29: R2 | C29: Goody Bag (Buku/Makanan Sehat/Oleh-oleh) | D29: =200000*D7 -> 262000 | E29: =200000*E7 -> 302000 | F29: =200000*F7 -> 256000 | G29: =200000*G7 -> 200000 | H29: =200000*H7 -> 290000 | I29: =200000*I7 -> 290000 | J29: =200000*J7 -> 290000 | K29: =200000*K7 -> 250000 | ... N29: =200000*N7 -> 298000 | O29: Pcs | P29: 0
B30: L1 | C30: Goody Bag (Buku/Makanan Sehat/Oleh-oleh) | D30: =200000*D7*80% -> 209600 | E30: =200000*E7*80% -> 241600 | F30: =200000*F7*80% -> 204800 | G30: =200000*G7*80% -> 160000 | H30: =200000*H7*80% -> 232000 | I30: =200000*I7*80% -> 232000 | J30: =200000*J7*80% -> 232000 | K30: =200000*K7*80% -> 200000 | ... N30: =200000*N7*80% -> 238400 | O30: Pcs | P30: 0
B31: L2 | C31: Goody Bag (Buku/Makanan Sehat/Oleh-oleh) | D31: =200000*D7*120% -> 314400 | E31: =200000*E7*120% -> 362400 | F31: =200000*F7*120% -> 307200 | G31: =200000*G7*120% -> 240000 | H31: =200000*H7*120% -> 348000 | I31: =200000*I7*120% -> 348000 | J31: =200000*J7*120% -> 348000 | K31: =200000*K7*120% -> 300000 | ... N31: =200000*N7*120% -> 357600 | O31: Pcs | P31: 0
D32: Sumatera (LA-1) | E32: Jakarta (LA-1) | F32: Bandung (LA-2) | G32: Semarang (LA-3) | H32: Surabaya (LA-3) | I32: Bali (LA-3) | J32: Nusa Tenggara (LA-3) | K32: Kalimantan (LA-4) | L32: Sulawesi (LA-4) | M32: Maluku (LA-4) | N32: Papua (LA-4)
B33: R1 | C33: Akomodasi Hotel Fasilitator (2 org/kamar sd BP3 & 1 org/kamar BP2 & 1) | D33: =600000*D7 -> 786000 | E33: =600000*E7 -> 906000 | F33: =600000*F7 -> 768000 | G33: =600000*G7 -> 600000 | H33: =600000*H7 -> 870000 | I33: =600000*I7 -> 870000 | J33: =600000*J7 -> 870000 | K33: =600000*K7 -> 750000 | ... N33: =600000*N7 -> 894000 | O33: Hari | P33: 0
B34: R2 | C34: Akomodasi Hotel Fasilitator (2 org/kamar sd BP3 & 1 org/kamar BP2 & 1) | D34: =800000*D7 -> 1048000 | E34: =800000*E7 -> 1208000 | F34: =800000*F7 -> 1024000 | G34: =800000*G7 -> 800000 | H34: =800000*H7 -> 1160000 | I34: =800000*I7 -> 1160000 | J34: =800000*J7 -> 1160000 | K34: =800000*K7 -> 1000000 | ... N34: =800000*N7 -> 1192000 | O34: Hari | P34: 0
B35: L1 | C35: Akomodasi Hotel Fasilitator (2 org/kamar sd BP3 & 1 org/kamar BP2 & 1) | D35: =800000*D7*80% -> 838400 | E35: =800000*E7*80% -> 966400 | F35: =800000*F7*80% -> 819200 | G35: =800000*G7*80% -> 640000 | H35: =800000*H7*80% -> 928000 | I35: =800000*I7*80% -> 928000 | J35: =800000*J7*80% -> 928000 | K35: =800000*K7*80% -> 800000 | ... N35: =800000*N7*80% -> 953600 | O35: Hari | P35: 0
B36: L2 | C36: Akomodasi Hotel Fasilitator (2 org/kamar sd BP3 & 1 org/kamar BP2 & 1) | D36: =800000*D7*120% -> 1257600 | E36: =800000*E7*120% -> 1449600 | F36: =800000*F7*120% -> 1228800 | G36: =800000*G7*120% -> 960000 | H36: =800000*H7*120% -> 1392000 | I36: =800000*I7*120% -> 1392000 | J36: =800000*J7*120% -> 1392000 | K36: =800000*K7*120% -> 1200000 | ... N36: =800000*N7*120% -> 1430400 | O36: Hari | P36: 0
D37: Sumatera (LA-1) | E37: Jakarta (LA-1) | F37: Bandung (LA-2) | G37: Semarang (LA-3) | H37: Surabaya (LA-3) | I37: Bali (LA-3) | J37: Nusa Tenggara (LA-3) | K37: Kalimantan (LA-4) | L37: Sulawesi (LA-4) | M37: Maluku (LA-4) | N37: Papua (LA-4)
B38: R1 | C38: Perlengkapan Kelas (Flipchart, Spidol, Baterai, Kertas, dll) | D38: 500000 | E38: 500000 | F38: 500000 | G38: 500000 | H38: 500000 | I38: 500000 | J38: 500000 | K38: 500000 | L38: 500000 | M38: 500000 | N38: 500000 | O38: Event | P38: 1
B39: R2 | C39: Perlengkapan Kelas (Flipchart, Spidol, Baterai, Kertas, dll) | D39: 500000 | E39: =500000*E7 -> 755000 | F39: 500000 | G39: 500000 | H39: 500000 | I39: 500000 | J39: 500000 | K39: 500000 | L39: 500000 | M39: 500000 | N39: 500000 | O39: Event | P39: 1
B40: L1 | C40: Perlengkapan Kelas (Flipchart, Spidol, Baterai, Kertas, dll) | D40: 500000 | E40: 500000 | F40: 500000 | G40: 500000 | H40: 500000 | I40: 500000 | J40: 500000 | K40: 500000 | L40: 500000 | M40: 500000 | N40: 500000 | O40: Event | P40: 1
B41: L2 | C41: Perlengkapan Kelas (Flipchart, Spidol, Baterai, Kertas, dll) | D41: 500000 | E41: 500000 | F41: 500000 | G41: 500000 | H41: 500000 | I41: 500000 | J41: 500000 | K41: 500000 | L41: 500000 | M41: 500000 | N41: 500000 | O41: Event | P41: 1
D42: Sumatera (LA-1) | E42: Jakarta (LA-1) | F42: Bandung (LA-2) | G42: Semarang (LA-3) | H42: Surabaya (LA-3) | I42: Bali (LA-3) | J42: Nusa Tenggara (LA-3) | K42: Kalimantan (LA-4) | L42: Sulawesi (LA-4) | M42: Maluku (LA-4) | N42: Papua (LA-4)
B43: R1 | C43: Alat dan Bahan untuk Praktikum/Game (Bila diperlukan) | D43: =1500000*D7 -> 1965000 | E43: =1500000*E7 -> 2265000 | F43: =1500000*F7 -> 1920000 | G43: =1500000*G7 -> 1500000 | H43: =1500000*H7 -> 2175000 | I43: =1500000*I7 -> 2175000 | J43: =1500000*J7 -> 2175000 | K43: =1500000*K7 -> 1875000 | ... N43: =1500000*N7 -> 2235000 | O43: Pax | P43: 0
B44: R2 | C44: Alat dan Bahan untuk Praktikum/Game (Bila diperlukan) | D44: =1500000*D7 -> 1965000 | E44: =1500000*E7 -> 2265000 | F44: =1500000*F7 -> 1920000 | G44: =1500000*G7 -> 1500000 | H44: =1500000*H7 -> 2175000 | I44: =1500000*I7 -> 2175000 | J44: =1500000*J7 -> 2175000 | K44: =1500000*K7 -> 1875000 | ... N44: =1500000*N7 -> 2235000 | O44: Pax | P44: 0
...
